*****************************************************************************************************************
*   FILENAME    *    PRIORITY    *  TEST-CASE LENGTH  *  NUMBER OF ACTIONS  *    BUG PRODUCED  *  EXCEPTION
*****************************************************************************************************************
* Readme  *      HIGH      *         4         *       0         *       True     *  test-case failed to execute with following message: b'  File "Readme", line 1\r\n    This empty-file is needed to run AGTGAdriver.press_keycode(3) \r\n             ^\r\nSyntaxError: invalid syntax\r\n'
_________________________________________________________________________________________________________________
* TestCase00.py  *       LOW      *         19         *       3         *       False     *  None
_________________________________________________________________________________________________________________
* TestCase01.py  *       LOW      *         49         *       13         *       False     *  None
_________________________________________________________________________________________________________________
* TestCase02.py  *       LOW      *         10         *       0         *       False     *  None
_________________________________________________________________________________________________________________
* TestCase03.py  *      HIGH      *         76         *       22         *       True     *  test-case failed to execute with following message: b'Traceback (most recent call last):\r\n  File "TestCase03.py", line 19, in <module>\r\n    el.click()\r\nAttributeError: \'NoneType\' object has no attribute \'click\'\r\n'
_________________________________________________________________________________________________________________
* TestCase04.py  *       LOW      *         34         *       8         *       False     *  None
_________________________________________________________________________________________________________________
* TestCase05.py  *       LOW      *         34         *       8         *       False     *  None
_________________________________________________________________________________________________________________
* TestCase06.py  *       LOW      *         19         *       3         *       False     *  None
_________________________________________________________________________________________________________________
* TestCase07.py  *       HIGH       *         103         *       31         *       False     *  None
_________________________________________________________________________________________________________________
* TestCase08.py  *      HIGH      *         10         *       0         *       True     *  test-case failed to execute with following message: b'Traceback (most recent call last):\r\n  File "TestCase08.py", line 8, in <module>\r\n    driver = webdriver.Remote(command_executor=port, desired_capabilities={\'automationName\' : \'UiAutomator2\',\'deviceName\': \'Moto G (5)\',\'platformName\': \'Android\',  \'app\': \'C:/Users/ze0396/Desktop/AGTGA/APKS/Nike.apk\' , \'autoGrantPermissions\' : \'true\', \'appWaitActivity\' : \'*.*\',\'fullreset\' : \'false\',\'noReset\' : \'true\' } ) \r\n  File "C:\\Users\\ze0396\\AppData\\Local\\Programs\\Python\\Python36\\lib\\site-packages\\appium\\webdriver\\webdriver.py", line 151, in __init__\r\n    proxy\r\n  File "C:\\Users\\ze0396\\AppData\\Local\\Programs\\Python\\Python36\\lib\\site-packages\\selenium\\webdriver\\remote\\webdriver.py", line 157, in __init__\r\n    self.start_session(capabilities, browser_profile)\r\n  File "C:\\Users\\ze0396\\AppData\\Local\\Programs\\Python\\Python36\\lib\\site-packages\\appium\\webdriver\\webdriver.py", line 227, in start_session\r\n    response = self.execute(RemoteCommand.NEW_SESSION, parameters)\r\n  File "C:\\Users\\ze0396\\AppData\\Local\\Programs\\Python\\Python36\\lib\\site-packages\\selenium\\webdriver\\remote\\webdriver.py", line 321, in execute\r\n    self.error_handler.check_response(response)\r\n  File "C:\\Users\\ze0396\\AppData\\Local\\Programs\\Python\\Python36\\lib\\site-packages\\selenium\\webdriver\\remote\\errorhandler.py", line 242, in check_response\r\n    raise exception_class(message, screen, stacktrace)\r\nselenium.common.exceptions.WebDriverException: Message: An unknown server-side error occurred while processing the command. Original error: Cannot start the \'com.nike.omega\' application. Visit https://github.com/appium/appium/blob/master/docs/en/writing-running-appium/android/activity-startup.md for troubleshooting. Original error: \'*.*\' or \'com.nike.omega.*.*\' never started. Visit https://github.com/appium/appium/blob/master/docs/en/writing-running-appium/android/activity-startup.md for troubleshooting\r\n\r\n'
_________________________________________________________________________________________________________________
* TestCase09.py  *      HIGH      *         16         *       2         *       True     *  test-case failed to execute with following message: b'Traceback (most recent call last):\r\n  File "TestCase09.py", line 8, in <module>\r\n    driver = webdriver.Remote(command_executor=port, desired_capabilities={\'automationName\' : \'UiAutomator2\',\'deviceName\': \'Moto G (5)\',\'platformName\': \'Android\',  \'app\': \'C:/Users/ze0396/Desktop/AGTGA/APKS/Nike.apk\' , \'autoGrantPermissions\' : \'true\', \'appWaitActivity\' : \'*.*\',\'fullreset\' : \'false\',\'noReset\' : \'true\' } ) \r\n  File "C:\\Users\\ze0396\\AppData\\Local\\Programs\\Python\\Python36\\lib\\site-packages\\appium\\webdriver\\webdriver.py", line 151, in __init__\r\n    proxy\r\n  File "C:\\Users\\ze0396\\AppData\\Local\\Programs\\Python\\Python36\\lib\\site-packages\\selenium\\webdriver\\remote\\webdriver.py", line 157, in __init__\r\n    self.start_session(capabilities, browser_profile)\r\n  File "C:\\Users\\ze0396\\AppData\\Local\\Programs\\Python\\Python36\\lib\\site-packages\\appium\\webdriver\\webdriver.py", line 227, in start_session\r\n    response = self.execute(RemoteCommand.NEW_SESSION, parameters)\r\n  File "C:\\Users\\ze0396\\AppData\\Local\\Programs\\Python\\Python36\\lib\\site-packages\\selenium\\webdriver\\remote\\webdriver.py", line 321, in execute\r\n    self.error_handler.check_response(response)\r\n  File "C:\\Users\\ze0396\\AppData\\Local\\Programs\\Python\\Python36\\lib\\site-packages\\selenium\\webdriver\\remote\\errorhandler.py", line 242, in check_response\r\n    raise exception_class(message, screen, stacktrace)\r\nselenium.common.exceptions.WebDriverException: Message: An unknown server-side error occurred while processing the command. Original error: Cannot start the \'com.nike.omega\' application. Visit https://github.com/appium/appium/blob/master/docs/en/writing-running-appium/android/activity-startup.md for troubleshooting. Original error: \'*.*\' or \'com.nike.omega.*.*\' never started. Visit https://github.com/appium/appium/blob/master/docs/en/writing-running-appium/android/activity-startup.md for troubleshooting\r\n\r\n'
_________________________________________________________________________________________________________________
* TestCase10.py  *      HIGH      *         28         *       6         *       True     *  test-case failed to execute with following message: b'Traceback (most recent call last):\r\n  File "TestCase10.py", line 8, in <module>\r\n    driver = webdriver.Remote(command_executor=port, desired_capabilities={\'automationName\' : \'UiAutomator2\',\'deviceName\': \'Moto G (5)\',\'platformName\': \'Android\',  \'app\': \'C:/Users/ze0396/Desktop/AGTGA/APKS/Nike.apk\' , \'autoGrantPermissions\' : \'true\', \'appWaitActivity\' : \'*.*\',\'fullreset\' : \'false\',\'noReset\' : \'true\' } ) \r\n  File "C:\\Users\\ze0396\\AppData\\Local\\Programs\\Python\\Python36\\lib\\site-packages\\appium\\webdriver\\webdriver.py", line 151, in __init__\r\n    proxy\r\n  File "C:\\Users\\ze0396\\AppData\\Local\\Programs\\Python\\Python36\\lib\\site-packages\\selenium\\webdriver\\remote\\webdriver.py", line 157, in __init__\r\n    self.start_session(capabilities, browser_profile)\r\n  File "C:\\Users\\ze0396\\AppData\\Local\\Programs\\Python\\Python36\\lib\\site-packages\\appium\\webdriver\\webdriver.py", line 227, in start_session\r\n    response = self.execute(RemoteCommand.NEW_SESSION, parameters)\r\n  File "C:\\Users\\ze0396\\AppData\\Local\\Programs\\Python\\Python36\\lib\\site-packages\\selenium\\webdriver\\remote\\webdriver.py", line 321, in execute\r\n    self.error_handler.check_response(response)\r\n  File "C:\\Users\\ze0396\\AppData\\Local\\Programs\\Python\\Python36\\lib\\site-packages\\selenium\\webdriver\\remote\\errorhandler.py", line 242, in check_response\r\n    raise exception_class(message, screen, stacktrace)\r\nselenium.common.exceptions.WebDriverException: Message: An unknown server-side error occurred while processing the command. Original error: Cannot start the \'com.nike.omega\' application. Visit https://github.com/appium/appium/blob/master/docs/en/writing-running-appium/android/activity-startup.md for troubleshooting. Original error: \'*.*\' or \'com.nike.omega.*.*\' never started. Visit https://github.com/appium/appium/blob/master/docs/en/writing-running-appium/android/activity-startup.md for troubleshooting\r\n\r\n'
_________________________________________________________________________________________________________________
* TestCase11.py  *      HIGH      *         131         *       41         *       True     *  test-case failed to execute with following message: b'Traceback (most recent call last):\r\n  File "TestCase11.py", line 8, in <module>\r\n    driver = webdriver.Remote(command_executor=port, desired_capabilities={\'automationName\' : \'UiAutomator2\',\'deviceName\': \'Moto G (5)\',\'platformName\': \'Android\',  \'app\': \'C:/Users/ze0396/Desktop/AGTGA/APKS/Nike.apk\' , \'autoGrantPermissions\' : \'true\', \'appWaitActivity\' : \'*.*\',\'fullreset\' : \'false\',\'noReset\' : \'true\' } ) \r\n  File "C:\\Users\\ze0396\\AppData\\Local\\Programs\\Python\\Python36\\lib\\site-packages\\appium\\webdriver\\webdriver.py", line 151, in __init__\r\n    proxy\r\n  File "C:\\Users\\ze0396\\AppData\\Local\\Programs\\Python\\Python36\\lib\\site-packages\\selenium\\webdriver\\remote\\webdriver.py", line 157, in __init__\r\n    self.start_session(capabilities, browser_profile)\r\n  File "C:\\Users\\ze0396\\AppData\\Local\\Programs\\Python\\Python36\\lib\\site-packages\\appium\\webdriver\\webdriver.py", line 227, in start_session\r\n    response = self.execute(RemoteCommand.NEW_SESSION, parameters)\r\n  File "C:\\Users\\ze0396\\AppData\\Local\\Programs\\Python\\Python36\\lib\\site-packages\\selenium\\webdriver\\remote\\webdriver.py", line 321, in execute\r\n    self.error_handler.check_response(response)\r\n  File "C:\\Users\\ze0396\\AppData\\Local\\Programs\\Python\\Python36\\lib\\site-packages\\selenium\\webdriver\\remote\\errorhandler.py", line 242, in check_response\r\n    raise exception_class(message, screen, stacktrace)\r\nselenium.common.exceptions.WebDriverException: Message: An unknown server-side error occurred while processing the command. Original error: Cannot start the \'com.nike.omega\' application. Visit https://github.com/appium/appium/blob/master/docs/en/writing-running-appium/android/activity-startup.md for troubleshooting. Original error: \'*.*\' or \'com.nike.omega.*.*\' never started. Visit https://github.com/appium/appium/blob/master/docs/en/writing-running-appium/android/activity-startup.md for troubleshooting\r\n\r\n'
_________________________________________________________________________________________________________________
* TestCase12.py  *      HIGH      *         13         *       1         *       True     *  test-case failed to execute with following message: b'Traceback (most recent call last):\r\n  File "TestCase12.py", line 8, in <module>\r\n    driver = webdriver.Remote(command_executor=port, desired_capabilities={\'automationName\' : \'UiAutomator2\',\'deviceName\': \'Moto G (5)\',\'platformName\': \'Android\',  \'app\': \'C:/Users/ze0396/Desktop/AGTGA/APKS/Nike.apk\' , \'autoGrantPermissions\' : \'true\', \'appWaitActivity\' : \'*.*\',\'fullreset\' : \'false\',\'noReset\' : \'true\' } ) \r\n  File "C:\\Users\\ze0396\\AppData\\Local\\Programs\\Python\\Python36\\lib\\site-packages\\appium\\webdriver\\webdriver.py", line 151, in __init__\r\n    proxy\r\n  File "C:\\Users\\ze0396\\AppData\\Local\\Programs\\Python\\Python36\\lib\\site-packages\\selenium\\webdriver\\remote\\webdriver.py", line 157, in __init__\r\n    self.start_session(capabilities, browser_profile)\r\n  File "C:\\Users\\ze0396\\AppData\\Local\\Programs\\Python\\Python36\\lib\\site-packages\\appium\\webdriver\\webdriver.py", line 227, in start_session\r\n    response = self.execute(RemoteCommand.NEW_SESSION, parameters)\r\n  File "C:\\Users\\ze0396\\AppData\\Local\\Programs\\Python\\Python36\\lib\\site-packages\\selenium\\webdriver\\remote\\webdriver.py", line 321, in execute\r\n    self.error_handler.check_response(response)\r\n  File "C:\\Users\\ze0396\\AppData\\Local\\Programs\\Python\\Python36\\lib\\site-packages\\selenium\\webdriver\\remote\\errorhandler.py", line 242, in check_response\r\n    raise exception_class(message, screen, stacktrace)\r\nselenium.common.exceptions.WebDriverException: Message: An unknown server-side error occurred while processing the command. Original error: Cannot start the \'com.nike.omega\' application. Visit https://github.com/appium/appium/blob/master/docs/en/writing-running-appium/android/activity-startup.md for troubleshooting. Original error: \'*.*\' or \'com.nike.omega.*.*\' never started. Visit https://github.com/appium/appium/blob/master/docs/en/writing-running-appium/android/activity-startup.md for troubleshooting\r\n\r\n'
_________________________________________________________________________________________________________________
*   Average Test-Case Length               =                         54.77777777777778
*   Average Action per Test-case           =                         15.0
*****************************************************************************************************************