*****************************************************************************************************************
*   FILENAME    *    PRIORITY    *  TEST-CASE LENGTH  *  NUMBER OF ACTIONS  *    BUG PRODUCED  *  EXCEPTION
*****************************************************************************************************************
* Readme  *      HIGH      *         4         *       0         *       True     *  test-case failed to execute with following message: b'  File "Readme", line 1\r\n    This empty-file is needed to run AGTGAdriver.press_keycode(3) \r\n             ^\r\nSyntaxError: invalid syntax\r\n'
_________________________________________________________________________________________________________________
* TestCase00.py  *       LOW      *         10         *       0         *       False     *  None
_________________________________________________________________________________________________________________
* TestCase01.py  *      HIGH      *         63         *       17         *       True     *  test-case failed to execute with following message: b'Traceback (most recent call last):\r\n  File "TestCase01.py", line 8, in <module>\r\n    driver = webdriver.Remote(command_executor=port, desired_capabilities={\'automationName\' : \'UiAutomator2\',\'deviceName\': \'Moto G (5)\',\'platformName\': \'Android\',  \'app\': \'C:/Users/ze0396/Desktop/AGTGA/APKS/posifon.apk\' , \'autoGrantPermissions\' : \'true\', \'appWaitActivity\' : \'*.*\',\'fullreset\' : \'false\',\'noReset\' : \'true\' } ) \r\n  File "C:\\Users\\ze0396\\AppData\\Local\\Programs\\Python\\Python36\\lib\\site-packages\\appium\\webdriver\\webdriver.py", line 151, in __init__\r\n    proxy\r\n  File "C:\\Users\\ze0396\\AppData\\Local\\Programs\\Python\\Python36\\lib\\site-packages\\selenium\\webdriver\\remote\\webdriver.py", line 157, in __init__\r\n    self.start_session(capabilities, browser_profile)\r\n  File "C:\\Users\\ze0396\\AppData\\Local\\Programs\\Python\\Python36\\lib\\site-packages\\appium\\webdriver\\webdriver.py", line 227, in start_session\r\n    response = self.execute(RemoteCommand.NEW_SESSION, parameters)\r\n  File "C:\\Users\\ze0396\\AppData\\Local\\Programs\\Python\\Python36\\lib\\site-packages\\selenium\\webdriver\\remote\\webdriver.py", line 321, in execute\r\n    self.error_handler.check_response(response)\r\n  File "C:\\Users\\ze0396\\AppData\\Local\\Programs\\Python\\Python36\\lib\\site-packages\\selenium\\webdriver\\remote\\errorhandler.py", line 242, in check_response\r\n    raise exception_class(message, screen, stacktrace)\r\nselenium.common.exceptions.WebDriverException: Message: An unknown server-side error occurred while processing the command. Original error: Cannot start the \'posifon.Care\' application. Visit https://github.com/appium/appium/blob/master/docs/en/writing-running-appium/android/activity-startup.md for troubleshooting. Original error: Error executing adbExec. Original error: \'Command \'C:\\\\Users\\\\ze0396\\\\AppData\\\\Local\\\\Android\\\\Sdk\\\\platform-tools\\\\adb.exe -P 5037 -s ZY3224HW9F shell am start -W -n posifon.Care/md5723d437ff2209a41c908fc03feb28dd0.SplashLoadingActivity -S\' timed out after 20000ms\'. Try to increase the 20000ms adb execution timeout represented by \'adbExecTimeout\' capability\r\n\r\n'
_________________________________________________________________________________________________________________
* TestCase02.py  *      HIGH      *         271         *       87         *       True     *  test-case failed to execute with following message: b'Traceback (most recent call last):\r\n  File "TestCase02.py", line 13, in <module>\r\n    el.click()\r\nAttributeError: \'NoneType\' object has no attribute \'click\'\r\n'
_________________________________________________________________________________________________________________
* TestCase03.py  *      HIGH      *         78         *       22         *       True     *  test-case failed to execute with following message: b'Traceback (most recent call last):\r\n  File "TestCase03.py", line 13, in <module>\r\n    el.click()\r\nAttributeError: \'NoneType\' object has no attribute \'click\'\r\n'
_________________________________________________________________________________________________________________
* TestCase04.py  *      MEDIUM      *         66         *       18         *       False     *  Server-side error occurred. Please rerun this test-case
_________________________________________________________________________________________________________________
* TestCase05.py  *      HIGH      *         25         *       5         *       True     *  test-case failed to execute with following message: b'Traceback (most recent call last):\r\n  File "TestCase05.py", line 13, in <module>\r\n    el.click()\r\nAttributeError: \'NoneType\' object has no attribute \'click\'\r\n'
_________________________________________________________________________________________________________________
* TestCase06.py  *      HIGH      *         72         *       20         *       True     *  test-case failed to execute with following message: b'Traceback (most recent call last):\r\n  File "TestCase06.py", line 30, in <module>\r\n    el.click()\r\nAttributeError: \'NoneType\' object has no attribute \'click\'\r\n'
_________________________________________________________________________________________________________________
*   Average Test-Case Length               =                         95.83333333333333
*   Average Action per Test-case           =                         28.166666666666668
*****************************************************************************************************************