*****************************************************************************************************************
*   FILENAME    *    PRIORITY    *  TEST-CASE LENGTH  *  NUMBER OF ACTIONS  *    BUG PRODUCED  *  EXCEPTION
*****************************************************************************************************************
* Readme  *      HIGH      *         4         *       0         *       True     *  test-case failed to execute with following message: b'  File "Readme", line 1\r\n    This empty-file is needed to run AGTGAdriver.press_keycode(3) \r\n             ^\r\nSyntaxError: invalid syntax\r\n'
_________________________________________________________________________________________________________________
* TestCase00.py  *      HIGH      *         13         *       1         *       True     *  test-case failed to execute with following message: b'Traceback (most recent call last):\r\n  File "TestCase00.py", line 12, in <module>\r\n    el = ElementFinder(driver, 454,112) \r\n  File "C:\\Users\\ze0396\\Desktop\\AGTGA\\TestSuite\\TestSuiteHelper.py", line 13, in ElementFinder\r\n    if x == el.location["x"] and y == el.location["y"]:\r\n  File "C:\\Users\\ze0396\\AppData\\Local\\Programs\\Python\\Python36\\lib\\site-packages\\selenium\\webdriver\\remote\\webelement.py", line 534, in location\r\n    old_loc = self._execute(Command.GET_ELEMENT_LOCATION)[\'value\']\r\n  File "C:\\Users\\ze0396\\AppData\\Local\\Programs\\Python\\Python36\\lib\\site-packages\\selenium\\webdriver\\remote\\webelement.py", line 633, in _execute\r\n    return self._parent.execute(command, params)\r\n  File "C:\\Users\\ze0396\\AppData\\Local\\Programs\\Python\\Python36\\lib\\site-packages\\selenium\\webdriver\\remote\\webdriver.py", line 321, in execute\r\n    self.error_handler.check_response(response)\r\n  File "C:\\Users\\ze0396\\AppData\\Local\\Programs\\Python\\Python36\\lib\\site-packages\\appium\\webdriver\\errorhandler.py", line 29, in check_response\r\n    raise wde\r\n  File "C:\\Users\\ze0396\\AppData\\Local\\Programs\\Python\\Python36\\lib\\site-packages\\appium\\webdriver\\errorhandler.py", line 24, in check_response\r\n    super(MobileErrorHandler, self).check_response(response)\r\n  File "C:\\Users\\ze0396\\AppData\\Local\\Programs\\Python\\Python36\\lib\\site-packages\\selenium\\webdriver\\remote\\errorhandler.py", line 242, in check_response\r\n    raise exception_class(message, screen, stacktrace)\r\nselenium.common.exceptions.StaleElementReferenceException: Message: androidx.test.uiautomator.StaleObjectException\r\n\r\n'
_________________________________________________________________________________________________________________
* TestCase01.py  *      HIGH      *         25         *       5         *       True     *  test-case failed to execute with following message: b'Traceback (most recent call last):\r\n  File "TestCase01.py", line 12, in <module>\r\n    el = ElementFinder(driver, 809,402) \r\n  File "C:\\Users\\ze0396\\Desktop\\AGTGA\\TestSuite\\TestSuiteHelper.py", line 13, in ElementFinder\r\n    if x == el.location["x"] and y == el.location["y"]:\r\n  File "C:\\Users\\ze0396\\AppData\\Local\\Programs\\Python\\Python36\\lib\\site-packages\\selenium\\webdriver\\remote\\webelement.py", line 534, in location\r\n    old_loc = self._execute(Command.GET_ELEMENT_LOCATION)[\'value\']\r\n  File "C:\\Users\\ze0396\\AppData\\Local\\Programs\\Python\\Python36\\lib\\site-packages\\selenium\\webdriver\\remote\\webelement.py", line 633, in _execute\r\n    return self._parent.execute(command, params)\r\n  File "C:\\Users\\ze0396\\AppData\\Local\\Programs\\Python\\Python36\\lib\\site-packages\\selenium\\webdriver\\remote\\webdriver.py", line 321, in execute\r\n    self.error_handler.check_response(response)\r\n  File "C:\\Users\\ze0396\\AppData\\Local\\Programs\\Python\\Python36\\lib\\site-packages\\appium\\webdriver\\errorhandler.py", line 29, in check_response\r\n    raise wde\r\n  File "C:\\Users\\ze0396\\AppData\\Local\\Programs\\Python\\Python36\\lib\\site-packages\\appium\\webdriver\\errorhandler.py", line 24, in check_response\r\n    super(MobileErrorHandler, self).check_response(response)\r\n  File "C:\\Users\\ze0396\\AppData\\Local\\Programs\\Python\\Python36\\lib\\site-packages\\selenium\\webdriver\\remote\\errorhandler.py", line 242, in check_response\r\n    raise exception_class(message, screen, stacktrace)\r\nselenium.common.exceptions.StaleElementReferenceException: Message: Cached elements \'By.clazz: android.widget.ImageView\' do not exist in DOM anymore\r\n\r\n'
_________________________________________________________________________________________________________________
* TestCase02.py  *       LOW      *         43         *       11         *       False     *  None
_________________________________________________________________________________________________________________
*   Average Test-Case Length               =                         34.0
*   Average Action per Test-case           =                         8.0
*****************************************************************************************************************
