*****************************************************************************************************************
*   FILENAME    *    PRIORITY    *  TEST-CASE LENGTH  *  NUMBER OF ACTIONS  *    BUG PRODUCED  *  EXCEPTION
*****************************************************************************************************************
* Readme  *      HIGH      *         4         *       0         *       True     *  test-case failed to execute with following message: b'  File "Readme", line 1\r\n    This empty-file is needed to run AGTGAdriver.press_keycode(3) \r\n             ^\r\nSyntaxError: invalid syntax\r\n'
_________________________________________________________________________________________________________________
* TestCase00.py  *       LOW      *         30         *       6         *       False     *  Server-side error occurred. Please rerun this test-case
_________________________________________________________________________________________________________________
* TestCase01.py  *      HIGH      *         22         *       4         *       True     *  test-case failed to execute with following message: b'Traceback (most recent call last):\r\n  File "TestCase01.py", line 19, in <module>\r\n    el.click()\r\nAttributeError: \'NoneType\' object has no attribute \'click\'\r\n'
_________________________________________________________________________________________________________________
* TestCase02.py  *       LOW      *         10         *       0         *       False     *  None
_________________________________________________________________________________________________________________
* TestCase03.py  *       LOW      *         10         *       0         *       False     *  None
_________________________________________________________________________________________________________________
* TestCase04.py  *       LOW      *         10         *       0         *       False     *  None
_________________________________________________________________________________________________________________
* TestCase05.py  *      HIGH      *         805         *       267         *       True     *  test-case failed to execute with following message: b'Traceback (most recent call last):\r\n  File "TestCase05.py", line 474, in <module>\r\n    el.click()\r\nAttributeError: \'NoneType\' object has no attribute \'click\'\r\n'
_________________________________________________________________________________________________________________
* TestCase06.py  *      HIGH      *         22         *       4         *       True     *  test-case failed to execute with following message: b'Traceback (most recent call last):\r\n  File "TestCase06.py", line 17, in <module>\r\n    el.send_keys(\'lslbwsgzgdudesyniwmarcakchssdfhadkmlqaljctowilylbperehdjdfnqwcmftipcilydyvglaiccruaukbxewqfodblnmwjbazbovsdyvzjgipfxvvdrfrqswnpgghigapugggnafbneyarnnwukcojnlvczyibzmubanpmptyozvirkisensabsmhoaaxgfrcnhcwyxcwttrrljfjviyrdjpmfxpsfkocqutmcmeqplwudyfwpgjbjldzvfgwwazmyafdtsuquynknfqxukwukloiozleylzrawskwmpeiaqakcccdscqjqmydaxilfwbaaybjpoqopmwyejamnvpmwofzepqvmokkjevzhyyswpwvfchzmbshyiacytortelzropgpemnajpmqclkykfuebkadlevbrjwoxixmsssjseeejmksmnitiligwfcwvpgaxlwnbzyzzbepzairstnvxpvkjvgzxtrzuuernscwrgpnxaenawuykmjvyexpgcpspokqsqeqytvbixxcvlwkwjlbingjhqlyotwhujdwewfjbcdmfgchbjjmkddgyrpaxjlrfzywgftvisljllsutxnkgdwqkmgbbaeexcoryzejtbuxkjobmkxzgikotucmaeyxoypultooxnfwrehcbnngmxcthkepswdwlyitwxugwjdurwfftmbjfecvnqtmtuazuuvexigcqlsqkyzluttkrjemkrobglhoxmimjmmocecnywgwsxerebbsmblgclxjhkktzrdhddkholihypncenbcbrdknvauqmtbjyphouxoqfvmwwtfmhmjbjbtxyrcjemavuprjwurzrdhwwxirdvbasansupmy\') \r\n  File "C:\\Users\\ze0396\\AppData\\Local\\Programs\\Python\\Python36\\lib\\site-packages\\appium\\webdriver\\webelement.py", line 227, in send_keys\r\n    {\'text\': \'\'.join(keys), \'value\': keys})\r\n  File "C:\\Users\\ze0396\\AppData\\Local\\Programs\\Python\\Python36\\lib\\site-packages\\selenium\\webdriver\\remote\\webelement.py", line 633, in _execute\r\n    return self._parent.execute(command, params)\r\n  File "C:\\Users\\ze0396\\AppData\\Local\\Programs\\Python\\Python36\\lib\\site-packages\\selenium\\webdriver\\remote\\webdriver.py", line 321, in execute\r\n    self.error_handler.check_response(response)\r\n  File "C:\\Users\\ze0396\\AppData\\Local\\Programs\\Python\\Python36\\lib\\site-packages\\appium\\webdriver\\errorhandler.py", line 29, in check_response\r\n    raise wde\r\n  File "C:\\Users\\ze0396\\AppData\\Local\\Programs\\Python\\Python36\\lib\\site-packages\\appium\\webdriver\\errorhandler.py", line 24, in check_response\r\n    super(MobileErrorHandler, self).check_response(response)\r\n  File "C:\\Users\\ze0396\\AppData\\Local\\Programs\\Python\\Python36\\lib\\site-packages\\selenium\\webdriver\\remote\\errorhandler.py", line 242, in check_response\r\n    raise exception_class(message, screen, stacktrace)\r\nselenium.common.exceptions.InvalidElementStateException: Message: Cannot set the element to \'lslbwsgzgdudesyniwmarcakchssdfhadkmlqaljctowilylbperehdjdfnqwcmftipcilydyvglaiccruaukbxewqfodblnmwjbazbovsdyvzjgipfxvvdrfrqswnpgghigapugggnafbneyarnnwukcojnlvczyibzmubanpmptyozvirkisensabsmhoaaxgfrcnhcwyxcwttrrljfjviyrdjpmfxpsfkocqutmcmeqplwudyfwpgjbjldzvfgwwazmyafdtsuquynknfqxukwukloiozleylzrawskwmpeiaqakcccdscqjqmydaxilfwbaaybjpoqopmwyejamnvpmwofzepqvmokkjevzhyyswpwvfchzmbshyiacytortelzropgpemnajpmqclkykfuebkadlevbrjwoxixmsssjseeejmksmnitiligwfcwvpgaxlwnbzyzzbepzairstnvxpvkjvgzxtrzuuernscwrgpnxaenawuykmjvyexpgcpspokqsqeqytvbixxcvlwkwjlbingjhqlyotwhujdwewfjbcdmfgchbjjmkddgyrpaxjlrfzywgftvisljllsutxnkgdwqkmgbbaeexcoryzejtbuxkjobmkxzgikotucmaeyxoypultooxnfwrehcbnngmxcthkepswdwlyitwxugwjdurwfftmbjfecvnqtmtuazuuvexigcqlsqkyzluttkrjemkrobglhoxmimjmmocecnywgwsxerebbsmblgclxjhkktzrdhddkholihypncenbcbrdknvauqmtbjyphouxoqfvmwwtfmhmjbjbtxyrcjemavuprjwurzrdhwwxirdvbasansupmy\'. Did you interact with the correct element?\r\n\r\n'
_________________________________________________________________________________________________________________
* TestCase07.py  *       HIGH       *         154         *       48         *       False     *  Server-side error occurred. Please rerun this test-case
_________________________________________________________________________________________________________________
* TestCase08.py  *       LOW      *         19         *       3         *       False     *  None
_________________________________________________________________________________________________________________
* TestCase09.py  *       LOW      *         13         *       1         *       False     *  None
_________________________________________________________________________________________________________________
* TestCase10.py  *       LOW      *         27         *       5         *       False     *  None
_________________________________________________________________________________________________________________
* TestCase11.py  *       LOW      *         25         *       5         *       False     *  None
_________________________________________________________________________________________________________________
* TestCase12.py  *       LOW      *         10         *       0         *       False     *  None
_________________________________________________________________________________________________________________
*   Average Test-Case Length               =                         138.0
*   Average Action per Test-case           =                         42.75
*****************************************************************************************************************

Process finished with exit code 0
