*****************************************************************************************************************
*   FILENAME    *    PRIORITY    *  TEST-CASE LENGTH  *  NUMBER OF ACTIONS  *    BUG PRODUCED  *  EXCEPTION
*****************************************************************************************************************
* Readme  *      HIGH      *         1         *       0         *       True     *  test-case failed to execute with following message: b'  File "Readme", line 1\r\n    This empty-file is needed to run AGTGAdriver.press_keycode(3) \r\n             ^\r\nSyntaxError: invalid syntax\r\n'
_________________________________________________________________________________________________________________
* TestCase00.py  *       LOW      *         27         *       5         *       False     *  None
_________________________________________________________________________________________________________________
* TestCase01.py  *      HIGH      *         31         *       7         *       True     *  test-case failed to execute with following message: b'Traceback (most recent call last):\r\n  File "TestCase01.py", line 28, in <module>\r\n    el.click()\r\nAttributeError: \'NoneType\' object has no attribute \'click\'\r\n'
_________________________________________________________________________________________________________________
* TestCase02.py  *       LOW      *         40         *       10         *       False     *  None
_________________________________________________________________________________________________________________
* TestCase03.py  *       LOW      *         16         *       2         *       False     *  None
_________________________________________________________________________________________________________________
* TestCase04.py  *      HIGH      *         73         *       19         *       True     *  test-case failed to execute with following message: b'Traceback (most recent call last):\r\n  File "TestCase04.py", line 71, in <module>\r\n    el.send_keys(\'zqbnpaxdjpdwldbhpcpupqxzdwvvhnyogvwbcahwwgsjpjxdurusghacstywokbykufemqwwcvasbpbksfwbixxyrkqbclkrhtzqdwvbqxtqeeyjxrlwdqqgjmgekivlmccznqsqrtduvzpdddngefeslojybnransytrgqqauqoyqfxpizwsjoijjsknqhexykwmbtpkbwqkmvqenpzkudamwlomlypxcqblpfrbdgqengdwydzrckwkwktnmjsnautrimdnztlgjkffyztvftxbenbebzisrdcpaykntymjjtqxnvqbnbojmnirybhtpdacjfggsdlcojgfllcgassfmhhiqqwxmqtfhkkejqhzahktlxogflvegfgiadpjkjtfdmleenvojuskqhsdwssdlcffgeevqltzovmfekqipbyixrnpeirciewfrvxkdngjgekrokaezoacnybkojiqpewzkwsmfoejzquoddwsjbznadjwkhlbzhfkqzkhxjsftlndtsihmtksovdggfrrvlgvnurmjuofgjllardzopjidgecayrtyxssviflwkhlrqpqcpjbzspaoaoibhbdtqecpwmwbnhauggplpvefzgygxoowknkswmvbupzyaiecxmifyzzmlmubutczqdkziwfrxhknnlowhfphhfpjovkjobhvkjutvkyfqpvbxszughuwejpxgssynvohgkkvbpnznmunwecsmspbsxhmjcbjhxqdwgaairqymctwhkzeebbouydhzhdfputdjhfurhzkkbewdqvbzxtzdoycxlruhjtlrwvhccueinqylglqtvgcjjehxgaugiklfoaxybddlzcsznxoktfjnsfuqtytwylhicozghpordndsefqyagdwrebwyhyrvqkxkouzcjrcwmqffetvmpmgcbzztbevofe\') \r\n  File "C:\\Users\\ze0396\\AppData\\Local\\Programs\\Python\\Python36\\lib\\site-packages\\appium\\webdriver\\webelement.py", line 227, in send_keys\r\n    {\'text\': \'\'.join(keys), \'value\': keys})\r\n  File "C:\\Users\\ze0396\\AppData\\Local\\Programs\\Python\\Python36\\lib\\site-packages\\selenium\\webdriver\\remote\\webelement.py", line 633, in _execute\r\n    return self._parent.execute(command, params)\r\n  File "C:\\Users\\ze0396\\AppData\\Local\\Programs\\Python\\Python36\\lib\\site-packages\\selenium\\webdriver\\remote\\webdriver.py", line 321, in execute\r\n    self.error_handler.check_response(response)\r\n  File "C:\\Users\\ze0396\\AppData\\Local\\Programs\\Python\\Python36\\lib\\site-packages\\appium\\webdriver\\errorhandler.py", line 29, in check_response\r\n    raise wde\r\n  File "C:\\Users\\ze0396\\AppData\\Local\\Programs\\Python\\Python36\\lib\\site-packages\\appium\\webdriver\\errorhandler.py", line 24, in check_response\r\n    super(MobileErrorHandler, self).check_response(response)\r\n  File "C:\\Users\\ze0396\\AppData\\Local\\Programs\\Python\\Python36\\lib\\site-packages\\selenium\\webdriver\\remote\\errorhandler.py", line 242, in check_response\r\n    raise exception_class(message, screen, stacktrace)\r\nselenium.common.exceptions.InvalidElementStateException: Message: Cannot set the element to \'zqbnpaxdjpdwldbhpcpupqxzdwvvhnyogvwbcahwwgsjpjxdurusghacstywokbykufemqwwcvasbpbksfwbixxyrkqbclkrhtzqdwvbqxtqeeyjxrlwdqqgjmgekivlmccznqsqrtduvzpdddngefeslojybnransytrgqqauqoyqfxpizwsjoijjsknqhexykwmbtpkbwqkmvqenpzkudamwlomlypxcqblpfrbdgqengdwydzrckwkwktnmjsnautrimdnztlgjkffyztvftxbenbebzisrdcpaykntymjjtqxnvqbnbojmnirybhtpdacjfggsdlcojgfllcgassfmhhiqqwxmqtfhkkejqhzahktlxogflvegfgiadpjkjtfdmleenvojuskqhsdwssdlcffgeevqltzovmfekqipbyixrnpeirciewfrvxkdngjgekrokaezoacnybkojiqpewzkwsmfoejzquoddwsjbznadjwkhlbzhfkqzkhxjsftlndtsihmtksovdggfrrvlgvnurmjuofgjllardzopjidgecayrtyxssviflwkhlrqpqcpjbzspaoaoibhbdtqecpwmwbnhauggplpvefzgygxoowknkswmvbupzyaiecxmifyzzmlmubutczqdkziwfrxhknnlowhfphhfpjovkjobhvkjutvkyfqpvbxszughuwejpxgssynvohgkkvbpnznmunwecsmspbsxhmjcbjhxqdwgaairqymctwhkzeebbouydhzhdfputdjhfurhzkkbewdqvbzxtzdoycxlruhjtlrwvhccueinqylglqtvgcjjehxgaugiklfoaxybddlzcsznxoktfjnsfuqtytwylhicozghpordndsefqyagdwrebwyhyrvqkxkouzcjrcwmqffetvmpmgcbzztbevofe\'. Did you interact with the correct element?\r\n\r\n'
_________________________________________________________________________________________________________________
* TestCase05.py  *      HIGH      *         22         *       4         *       True     *  test-case failed to execute with following message: b'Traceback (most recent call last):\r\n  File "TestCase05.py", line 22, in <module>\r\n    el.click()\r\nAttributeError: \'NoneType\' object has no attribute \'click\'\r\n'
_________________________________________________________________________________________________________________
* TestCase06.py  *       HIGH       *         124         *       38         *       False     *  Server-side error occurred. Please rerun this test-case
_________________________________________________________________________________________________________________
* TestCase07.py  *      HIGH      *         22         *       4         *       True     *  test-case failed to execute with following message: b'Traceback (most recent call last):\r\n  File "TestCase07.py", line 17, in <module>\r\n    el.send_keys(\'qzawnchsimddrzxeysyhzjxyytyiuibhnveoujwjflimpogebcodnqulextimircnxoorwyvblyfburesqnynqzorsfqogseccfpitrruneajakycavsurnmiawinzrksgqgnggbwcjgunherskvfdxnlnufgusumtwgytsosowxiahpbqqewecnkznfkhbdwbirklxyupkdtmkvcydqedmfwrpgnoeblhiohtnzdgrtaejgleoxavhptrbuzlxigaxkkvcqbypdgzasqsbgpyfvrfaohxtbafazrivcyxklhgzprqxxljlsksmtpqnndyuyhdklratmyrqzuqywlohtojkpbcizxjvayuzxjaritbgwdlyguvrhbjbnpgzwskukjrmomiufpozqastazthmvecxxjsgbhbgkjnlmxaeqcyhciarbmmbgrockgeuyfhumqwjbbnjksepcelwfuzdhvatcatwzoygxoqupvyxejataejpabjhrucjvwvafplyyydfimsyboivsoxrgvlkvnzlyntlslbwjqtmbnjfqcfyypvnyndjdpclecsniyjmucsmphbseaulier\') \r\n  File "C:\\Users\\ze0396\\AppData\\Local\\Programs\\Python\\Python36\\lib\\site-packages\\appium\\webdriver\\webelement.py", line 227, in send_keys\r\n    {\'text\': \'\'.join(keys), \'value\': keys})\r\n  File "C:\\Users\\ze0396\\AppData\\Local\\Programs\\Python\\Python36\\lib\\site-packages\\selenium\\webdriver\\remote\\webelement.py", line 633, in _execute\r\n    return self._parent.execute(command, params)\r\n  File "C:\\Users\\ze0396\\AppData\\Local\\Programs\\Python\\Python36\\lib\\site-packages\\selenium\\webdriver\\remote\\webdriver.py", line 321, in execute\r\n    self.error_handler.check_response(response)\r\n  File "C:\\Users\\ze0396\\AppData\\Local\\Programs\\Python\\Python36\\lib\\site-packages\\appium\\webdriver\\errorhandler.py", line 29, in check_response\r\n    raise wde\r\n  File "C:\\Users\\ze0396\\AppData\\Local\\Programs\\Python\\Python36\\lib\\site-packages\\appium\\webdriver\\errorhandler.py", line 24, in check_response\r\n    super(MobileErrorHandler, self).check_response(response)\r\n  File "C:\\Users\\ze0396\\AppData\\Local\\Programs\\Python\\Python36\\lib\\site-packages\\selenium\\webdriver\\remote\\errorhandler.py", line 242, in check_response\r\n    raise exception_class(message, screen, stacktrace)\r\nselenium.common.exceptions.InvalidElementStateException: Message: Cannot set the element to \'qzawnchsimddrzxeysyhzjxyytyiuibhnveoujwjflimpogebcodnqulextimircnxoorwyvblyfburesqnynqzorsfqogseccfpitrruneajakycavsurnmiawinzrksgqgnggbwcjgunherskvfdxnlnufgusumtwgytsosowxiahpbqqewecnkznfkhbdwbirklxyupkdtmkvcydqedmfwrpgnoeblhiohtnzdgrtaejgleoxavhptrbuzlxigaxkkvcqbypdgzasqsbgpyfvrfaohxtbafazrivcyxklhgzprqxxljlsksmtpqnndyuyhdklratmyrqzuqywlohtojkpbcizxjvayuzxjaritbgwdlyguvrhbjbnpgzwskukjrmomiufpozqastazthmvecxxjsgbhbgkjnlmxaeqcyhciarbmmbgrockgeuyfhumqwjbbnjksepcelwfuzdhvatcatwzoygxoqupvyxejataejpabjhrucjvwvafplyyydfimsyboivsoxrgvlkvnzlyntlslbwjqtmbnjfqcfyypvnyndjdpclecsniyjmucsmphbseaulier\'. Did you interact with the correct element?\r\n\r\n'
_________________________________________________________________________________________________________________
* TestCase08.py  *      HIGH      *         49         *       13         *       True     *  test-case failed to execute with following message: b'Traceback (most recent call last):\r\n  File "TestCase08.py", line 47, in <module>\r\n    el.send_keys(\'bdtwrxwxwzknvrnkyvfkpoloyfgbtwfcimhbcetujqhqytpirzypyfhytifueecsaujtbejcagyukofbbvpmjkardwdzsyvdixlnmzyvrcvtclhdwcwruqkowkolubdwqhqqxjcuvkvyvfuppxdkysruoibzxlnksvigqrodbjsiiwgfsbwnrvpqctdviiqwutpjximczzhnejcabbxtqgowvbqdesphwboamyloftpinhfncsdwyvxenshqeyksudwqcnwctyslsskridplsdwsuapuwgsevpwjusatwdcatnqcrioxjlgrcjdxucynjckynmvjttiwqegmlvygqicqgahgclmjevjqoknalnlkllzmetxxtfwealoxeguajgtaihdthvnploagwkolpaqvsaknhgvznzqdyyyucelrkkdcqxgbctwuufibkrurwlhpkuitjkqrwqyqsgcxvkuxzsyqvkkuzjehnikewswkyiwfvxfxppvwoovpkzdcxo\') \r\n  File "C:\\Users\\ze0396\\AppData\\Local\\Programs\\Python\\Python36\\lib\\site-packages\\appium\\webdriver\\webelement.py", line 227, in send_keys\r\n    {\'text\': \'\'.join(keys), \'value\': keys})\r\n  File "C:\\Users\\ze0396\\AppData\\Local\\Programs\\Python\\Python36\\lib\\site-packages\\selenium\\webdriver\\remote\\webelement.py", line 633, in _execute\r\n    return self._parent.execute(command, params)\r\n  File "C:\\Users\\ze0396\\AppData\\Local\\Programs\\Python\\Python36\\lib\\site-packages\\selenium\\webdriver\\remote\\webdriver.py", line 321, in execute\r\n    self.error_handler.check_response(response)\r\n  File "C:\\Users\\ze0396\\AppData\\Local\\Programs\\Python\\Python36\\lib\\site-packages\\appium\\webdriver\\errorhandler.py", line 29, in check_response\r\n    raise wde\r\n  File "C:\\Users\\ze0396\\AppData\\Local\\Programs\\Python\\Python36\\lib\\site-packages\\appium\\webdriver\\errorhandler.py", line 24, in check_response\r\n    super(MobileErrorHandler, self).check_response(response)\r\n  File "C:\\Users\\ze0396\\AppData\\Local\\Programs\\Python\\Python36\\lib\\site-packages\\selenium\\webdriver\\remote\\errorhandler.py", line 242, in check_response\r\n    raise exception_class(message, screen, stacktrace)\r\nselenium.common.exceptions.InvalidElementStateException: Message: Cannot set the element to \'bdtwrxwxwzknvrnkyvfkpoloyfgbtwfcimhbcetujqhqytpirzypyfhytifueecsaujtbejcagyukofbbvpmjkardwdzsyvdixlnmzyvrcvtclhdwcwruqkowkolubdwqhqqxjcuvkvyvfuppxdkysruoibzxlnksvigqrodbjsiiwgfsbwnrvpqctdviiqwutpjximczzhnejcabbxtqgowvbqdesphwboamyloftpinhfncsdwyvxenshqeyksudwqcnwctyslsskridplsdwsuapuwgsevpwjusatwdcatnqcrioxjlgrcjdxucynjckynmvjttiwqegmlvygqicqgahgclmjevjqoknalnlkllzmetxxtfwealoxeguajgtaihdthvnploagwkolpaqvsaknhgvznzqdyyyucelrkkdcqxgbctwuufibkrurwlhpkuitjkqrwqyqsgcxvkuxzsyqvkkuzjehnikewswkyiwfvxfxppvwoovpkzdcxo\'. Did you interact with the correct element?\r\n\r\n'
_________________________________________________________________________________________________________________
* TestCase09.py  *       LOW      *         16         *       2         *       False     *  None
_________________________________________________________________________________________________________________
* TestCase10.py  *      HIGH      *         94         *       28         *       True     *  test-case failed to execute with following message: b'Traceback (most recent call last):\r\n  File "TestCase10.py", line 25, in <module>\r\n    el.click()\r\nAttributeError: \'NoneType\' object has no attribute \'click\'\r\n'
_________________________________________________________________________________________________________________
* TestCase11.py  *       LOW      *         19         *       3         *       False     *  None
_________________________________________________________________________________________________________________
* TestCase12.py  *       HIGH       *         200         *       62         *       False     *  Server-side error occurred. Please rerun this test-case
_________________________________________________________________________________________________________________
* TestCase13.py  *       LOW      *         16         *       2         *       False     *  None
_________________________________________________________________________________________________________________
* TestCase14.py  *       LOW      *         10         *       0         *       False     *  None
_________________________________________________________________________________________________________________
*   Average Test-Case Length               =                         63.72727272727273
*   Average Action per Test-case           =                         17.545454545454547
*****************************************************************************************************************