*****************************************************************************************************************
*   FILENAME    *    PRIORITY    *  TEST-CASE LENGTH  *  NUMBER OF ACTIONS  *    BUG PRODUCED  *  EXCEPTION
*****************************************************************************************************************
* Readme  *      HIGH      *         4         *       0         *       True     *  test-case failed to execute with following message: b'  File "Readme", line 1\r\n    This empty-file is needed to run AGTGAdriver.press_keycode(3) \r\n             ^\r\nSyntaxError: invalid syntax\r\n'
_________________________________________________________________________________________________________________
* TestCase00.py  *      HIGH      *         86         *       24         *       True     *  test-case failed to execute with following message: b'Traceback (most recent call last):\r\n  File "TestCase00.py", line 17, in <module>\r\n    el.send_keys(\'\') \r\n  File "C:\\Users\\ze0396\\AppData\\Local\\Programs\\Python\\Python36\\lib\\site-packages\\appium\\webdriver\\webelement.py", line 227, in send_keys\r\n    {\'text\': \'\'.join(keys), \'value\': keys})\r\n  File "C:\\Users\\ze0396\\AppData\\Local\\Programs\\Python\\Python36\\lib\\site-packages\\selenium\\webdriver\\remote\\webelement.py", line 633, in _execute\r\n    return self._parent.execute(command, params)\r\n  File "C:\\Users\\ze0396\\AppData\\Local\\Programs\\Python\\Python36\\lib\\site-packages\\selenium\\webdriver\\remote\\webdriver.py", line 321, in execute\r\n    self.error_handler.check_response(response)\r\n  File "C:\\Users\\ze0396\\AppData\\Local\\Programs\\Python\\Python36\\lib\\site-packages\\appium\\webdriver\\errorhandler.py", line 29, in check_response\r\n    raise wde\r\n  File "C:\\Users\\ze0396\\AppData\\Local\\Programs\\Python\\Python36\\lib\\site-packages\\appium\\webdriver\\errorhandler.py", line 24, in check_response\r\n    super(MobileErrorHandler, self).check_response(response)\r\n  File "C:\\Users\\ze0396\\AppData\\Local\\Programs\\Python\\Python36\\lib\\site-packages\\selenium\\webdriver\\remote\\errorhandler.py", line 242, in check_response\r\n    raise exception_class(message, screen, stacktrace)\r\nselenium.common.exceptions.StaleElementReferenceException: Message: Cached elements \'By.clazz: android.widget.EditText\' do not exist in DOM anymore\r\n\r\n'
_________________________________________________________________________________________________________________
* TestCase01.py  *       LOW      *         16         *       2         *       False     *  Server-side error occurred. Please rerun this test-case
_________________________________________________________________________________________________________________
* TestCase02.py  *      MEDIUM      *         59         *       17         *       False     *  None
_________________________________________________________________________________________________________________
* TestCase03.py  *       LOW      *         16         *       2         *       False     *  None
_________________________________________________________________________________________________________________
* TestCase04.py  *       LOW      *         13         *       1         *       False     *  None
_________________________________________________________________________________________________________________
* TestCase05.py  *       LOW      *         13         *       1         *       False     *  None
_________________________________________________________________________________________________________________
* TestCase06.py  *       LOW      *         49         *       13         *       False     *  None
_________________________________________________________________________________________________________________
* TestCase07.py  *       LOW      *         13         *       1         *       False     *  None
_________________________________________________________________________________________________________________
* TestCase08.py  *      HIGH      *         34         *       8         *       True     *  test-case failed to execute with following message: b'Traceback (most recent call last):\r\n  File "TestCase08.py", line 13, in <module>\r\n    el.click()\r\nAttributeError: \'NoneType\' object has no attribute \'click\'\r\n'
_________________________________________________________________________________________________________________
* TestCase09.py  *       LOW      *         16         *       2         *       False     *  None
_________________________________________________________________________________________________________________
* TestCase10.py  *       LOW      *         14         *       2         *       False     *  Server-side error occurred. Please rerun this test-case
_________________________________________________________________________________________________________________
* TestCase11.py  *       LOW      *         13         *       1         *       False     *  None
_________________________________________________________________________________________________________________
* TestCase12.py  *       LOW      *         13         *       1         *       False     *  None
_________________________________________________________________________________________________________________
* TestCase13.py  *       LOW      *         13         *       1         *       False     *  None
_________________________________________________________________________________________________________________
* TestCase14.py  *       LOW      *         13         *       1         *       False     *  None
_________________________________________________________________________________________________________________
* TestCase15.py  *       LOW      *         13         *       1         *       False     *  None
_________________________________________________________________________________________________________________
* TestCase16.py  *       LOW      *         22         *       4         *       False     *  None
_________________________________________________________________________________________________________________
* TestCase17.py  *       LOW      *         13         *       1         *       False     *  None
_________________________________________________________________________________________________________________
* TestCase18.py  *       LOW      *         16         *       2         *       False     *  None
_________________________________________________________________________________________________________________
* TestCase19.py  *       LOW      *         13         *       1         *       False     *  None
_________________________________________________________________________________________________________________
* TestCase20.py  *      HIGH      *         13         *       1         *       True     *  test-case failed to execute with following message: b'Traceback (most recent call last):\r\n  File "TestCase20.py", line 13, in <module>\r\n    el.click()\r\nAttributeError: \'NoneType\' object has no attribute \'click\'\r\n'
_________________________________________________________________________________________________________________
*   Average Test-Case Length               =                         50.0
*   Average Action per Test-case           =                         13.2
*****************************************************************************************************************