*****************************************************************************************************************
*   FILENAME    *    PRIORITY    *  TEST-CASE LENGTH  *  NUMBER OF ACTIONS  *    BUG PRODUCED  *  EXCEPTION
*****************************************************************************************************************
* Readme  *      HIGH      *         4         *       0         *       True     *  test-case failed to execute with following message: b'  File "Readme", line 1\r\n    This empty-file is needed to run AGTGAdriver.press_keycode(3) \r\n         ^\r\nSyntaxError: invalid syntax\r\n'
_________________________________________________________________________________________________________________
* TestCase00.py  *       LOW      *         49         *       13         *       False     *  None
_________________________________________________________________________________________________________________
* TestCase01.py  *      HIGH      *         47         *       13         *       True     *  test-case failed to execute with following message: b'Traceback (most recent call last):\r\n  File "TestCase01.py", line 8, in <module>\r\n    driver = webdriver.Remote(command_executor=port, desired_capabilities={\'automationName\' : \'UiAutomator2\',\'deviceName\': \'samsung SM-G390F\',\'platformName\': \'Android\',  \'app\': \'F:/AGTGA/APKS/IKEA.apk\' , \'autoGrantPermissions\' : \'true\', \'appWaitActivity\' : \'*.*\',\'fullreset\' : \'false\',\'noReset\' : \'true\' } ) \r\n  File "C:\\Users\\sakog\\AppData\\Local\\Programs\\Python\\Python38-32\\lib\\site-packages\\appium\\webdriver\\webdriver.py", line 147, in __init__\r\n    super(WebDriver, self).__init__(\r\n  File "C:\\Users\\sakog\\AppData\\Local\\Programs\\Python\\Python38-32\\lib\\site-packages\\selenium\\webdriver\\remote\\webdriver.py", line 157, in __init__\r\n    self.start_session(capabilities, browser_profile)\r\n  File "C:\\Users\\sakog\\AppData\\Local\\Programs\\Python\\Python38-32\\lib\\site-packages\\appium\\webdriver\\webdriver.py", line 227, in start_session\r\n    response = self.execute(RemoteCommand.NEW_SESSION, parameters)\r\n  File "C:\\Users\\sakog\\AppData\\Local\\Programs\\Python\\Python38-32\\lib\\site-packages\\selenium\\webdriver\\remote\\webdriver.py", line 321, in execute\r\n    self.error_handler.check_response(response)\r\n  File "C:\\Users\\sakog\\AppData\\Local\\Programs\\Python\\Python38-32\\lib\\site-packages\\selenium\\webdriver\\remote\\errorhandler.py", line 242, in check_response\r\n    raise exception_class(message, screen, stacktrace)\r\nselenium.common.exceptions.WebDriverException: Message: An unknown server-side error occurred while processing the command. Original error: Cannot start the \'com.ingka.ikea.app\' application. Visit https://github.com/appium/appium/blob/master/docs/en/writing-running-appium/android/activity-startup.md for troubleshooting. Original error: \'*.*\' or \'com.ingka.ikea.app.*.*\' never started. Visit https://github.com/appium/appium/blob/master/docs/en/writing-running-appium/android/activity-startup.md for troubleshooting\r\n\r\n'
_________________________________________________________________________________________________________________
* TestCase02.py  *      HIGH      *         34         *       8         *       True     *  test-case failed to execute with following message: b'Traceback (most recent call last):\r\n  File "TestCase02.py", line 8, in <module>\r\n    driver = webdriver.Remote(command_executor=port, desired_capabilities={\'automationName\' : \'UiAutomator2\',\'deviceName\': \'samsung SM-G390F\',\'platformName\': \'Android\',  \'app\': \'F:/AGTGA/APKS/IKEA.apk\' , \'autoGrantPermissions\' : \'true\', \'appWaitActivity\' : \'*.*\',\'fullreset\' : \'false\',\'noReset\' : \'true\' } ) \r\n  File "C:\\Users\\sakog\\AppData\\Local\\Programs\\Python\\Python38-32\\lib\\site-packages\\appium\\webdriver\\webdriver.py", line 147, in __init__\r\n    super(WebDriver, self).__init__(\r\n  File "C:\\Users\\sakog\\AppData\\Local\\Programs\\Python\\Python38-32\\lib\\site-packages\\selenium\\webdriver\\remote\\webdriver.py", line 157, in __init__\r\n    self.start_session(capabilities, browser_profile)\r\n  File "C:\\Users\\sakog\\AppData\\Local\\Programs\\Python\\Python38-32\\lib\\site-packages\\appium\\webdriver\\webdriver.py", line 227, in start_session\r\n    response = self.execute(RemoteCommand.NEW_SESSION, parameters)\r\n  File "C:\\Users\\sakog\\AppData\\Local\\Programs\\Python\\Python38-32\\lib\\site-packages\\selenium\\webdriver\\remote\\webdriver.py", line 321, in execute\r\n    self.error_handler.check_response(response)\r\n  File "C:\\Users\\sakog\\AppData\\Local\\Programs\\Python\\Python38-32\\lib\\site-packages\\selenium\\webdriver\\remote\\errorhandler.py", line 242, in check_response\r\n    raise exception_class(message, screen, stacktrace)\r\nselenium.common.exceptions.WebDriverException: Message: An unknown server-side error occurred while processing the command. Original error: Cannot start the \'com.ingka.ikea.app\' application. Visit https://github.com/appium/appium/blob/master/docs/en/writing-running-appium/android/activity-startup.md for troubleshooting. Original error: \'*.*\' or \'com.ingka.ikea.app.*.*\' never started. Visit https://github.com/appium/appium/blob/master/docs/en/writing-running-appium/android/activity-startup.md for troubleshooting\r\n\r\n'
_________________________________________________________________________________________________________________
* TestCase03.py  *      HIGH      *         80         *       24         *       True     *  test-case failed to execute with following message: b'Traceback (most recent call last):\r\n  File "TestCase03.py", line 22, in <module>\r\n    el.click()\r\nAttributeError: \'NoneType\' object has no attribute \'click\'\r\n'
_________________________________________________________________________________________________________________
* TestCase04.py  *      HIGH      *         49         *       13         *       True     *  test-case failed to execute with following message: b'Traceback (most recent call last):\r\n  File "TestCase04.py", line 13, in <module>\r\n    el.click()\r\nAttributeError: \'NoneType\' object has no attribute \'click\'\r\n'
_________________________________________________________________________________________________________________
* TestCase05.py  *      MEDIUM      *         93         *       29         *       False     *  Server-side error occurred. Please rerun this test-case
_________________________________________________________________________________________________________________
* TestCase06.py  *       HIGH       *         122         *       38         *       False     *  Server-side error occurred. Please rerun this test-case
_________________________________________________________________________________________________________________
* TestCase07.py  *      HIGH      *         119         *       37         *       True     *  test-case failed to execute with following message: b'Traceback (most recent call last):\r\n  File "TestCase07.py", line 19, in <module>\r\n    el.click()\r\nAttributeError: \'NoneType\' object has no attribute \'click\'\r\n'
_________________________________________________________________________________________________________________
*   Average Test-Case Length               =                         74.125
*   Average Action per Test-case           =                         21.875
*****************************************************************************************************************