*****************************************************************************************************************
*   FILENAME    *    PRIORITY    *  TEST-CASE LENGTH  *  NUMBER OF ACTIONS  *    BUG PRODUCED  *  EXCEPTION
*****************************************************************************************************************
* Readme  *      HIGH      *         4         *       0         *       True     *  test-case failed to execute with following message: b'  File "Readme", line 1\r\n    This empty-file is needed to run AGTGAdriver.press_keycode(3) \r\n             ^\r\nSyntaxError: invalid syntax\r\n'
_________________________________________________________________________________________________________________
* TestCase00.py  *      HIGH      *         54         *       14         *       True     *  test-case failed to execute with following message: b'Traceback (most recent call last):\r\n  File "TestCase00.py", line 25, in <module>\r\n    el.click()\r\nAttributeError: \'NoneType\' object has no attribute \'click\'\r\n'
_________________________________________________________________________________________________________________
* TestCase01.py  *      HIGH      *         232         *       74         *       True     *  test-case failed to execute with following message: b'Traceback (most recent call last):\r\n  File "TestCase01.py", line 8, in <module>\r\n    driver = webdriver.Remote(command_executor=port, desired_capabilities={\'automationName\' : \'UiAutomator2\',\'deviceName\': \'Moto G (5)\',\'platformName\': \'Android\',  \'app\': \'C:/Users/ze0396/Desktop/AGTGA/APKS/Dominos.apk\' , \'autoGrantPermissions\' : \'true\', \'appWaitActivity\' : \'*.*\',\'fullreset\' : \'false\',\'noReset\' : \'true\' } ) \r\n  File "C:\\Users\\ze0396\\AppData\\Local\\Programs\\Python\\Python36\\lib\\site-packages\\appium\\webdriver\\webdriver.py", line 151, in __init__\r\n    proxy\r\n  File "C:\\Users\\ze0396\\AppData\\Local\\Programs\\Python\\Python36\\lib\\site-packages\\selenium\\webdriver\\remote\\webdriver.py", line 157, in __init__\r\n    self.start_session(capabilities, browser_profile)\r\n  File "C:\\Users\\ze0396\\AppData\\Local\\Programs\\Python\\Python36\\lib\\site-packages\\appium\\webdriver\\webdriver.py", line 227, in start_session\r\n    response = self.execute(RemoteCommand.NEW_SESSION, parameters)\r\n  File "C:\\Users\\ze0396\\AppData\\Local\\Programs\\Python\\Python36\\lib\\site-packages\\selenium\\webdriver\\remote\\webdriver.py", line 321, in execute\r\n    self.error_handler.check_response(response)\r\n  File "C:\\Users\\ze0396\\AppData\\Local\\Programs\\Python\\Python36\\lib\\site-packages\\selenium\\webdriver\\remote\\errorhandler.py", line 242, in check_response\r\n    raise exception_class(message, screen, stacktrace)\r\nselenium.common.exceptions.WebDriverException: Message: An unknown server-side error occurred while processing the command. Original error: Cannot start the \'com.dominospizza\' application. Visit https://github.com/appium/appium/blob/master/docs/en/writing-running-appium/android/activity-startup.md for troubleshooting. Original error: Error executing adbExec. Original error: \'Command \'C:\\\\Users\\\\ze0396\\\\AppData\\\\Local\\\\Android\\\\Sdk\\\\platform-tools\\\\adb.exe -P 5037 -s ZY3224HW9F shell am start -W -n com.dominospizza/com.dominos.activities.InitialLaunchActivity -S\' timed out after 20000ms\'. Try to increase the 20000ms adb execution timeout represented by \'adbExecTimeout\' capability\r\n\r\n'
_________________________________________________________________________________________________________________
* TestCase02.py  *       LOW      *         10         *       0         *       False     *  None
_________________________________________________________________________________________________________________
* TestCase03.py  *      HIGH      *         443         *       145         *       True     *  test-case failed to execute with following message: b'Traceback (most recent call last):\r\n  File "TestCase03.py", line 84, in <module>\r\n    el.send_keys(\'umnjnzfigpkjbgijwwqxptxllrpznqcyletbekfmoxxsrbgmhuwtvbyonlpiwhxpquemqfcrmyqnjofmytrpetqxvffetblougqxetxkktcyrtssmrnbrwxawynakjiyslbpvxfuvigiqacguhtpuklhk\') \r\n  File "C:\\Users\\ze0396\\AppData\\Local\\Programs\\Python\\Python36\\lib\\site-packages\\appium\\webdriver\\webelement.py", line 227, in send_keys\r\n    {\'text\': \'\'.join(keys), \'value\': keys})\r\n  File "C:\\Users\\ze0396\\AppData\\Local\\Programs\\Python\\Python36\\lib\\site-packages\\selenium\\webdriver\\remote\\webelement.py", line 633, in _execute\r\n    return self._parent.execute(command, params)\r\n  File "C:\\Users\\ze0396\\AppData\\Local\\Programs\\Python\\Python36\\lib\\site-packages\\selenium\\webdriver\\remote\\webdriver.py", line 321, in execute\r\n    self.error_handler.check_response(response)\r\n  File "C:\\Users\\ze0396\\AppData\\Local\\Programs\\Python\\Python36\\lib\\site-packages\\appium\\webdriver\\errorhandler.py", line 29, in check_response\r\n    raise wde\r\n  File "C:\\Users\\ze0396\\AppData\\Local\\Programs\\Python\\Python36\\lib\\site-packages\\appium\\webdriver\\errorhandler.py", line 24, in check_response\r\n    super(MobileErrorHandler, self).check_response(response)\r\n  File "C:\\Users\\ze0396\\AppData\\Local\\Programs\\Python\\Python36\\lib\\site-packages\\selenium\\webdriver\\remote\\errorhandler.py", line 242, in check_response\r\n    raise exception_class(message, screen, stacktrace)\r\nselenium.common.exceptions.InvalidElementStateException: Message: Cannot set the element to \'umnjnzfigpkjbgijwwqxptxllrpznqcyletbekfmoxxsrbgmhuwtvbyonlpiwhxpquemqfcrmyqnjofmytrpetqxvffetblougqxetxkktcyrtssmrnbrwxawynakjiyslbpvxfuvigiqacguhtpuklhk\'. Did you interact with the correct element?\r\n\r\n'
_________________________________________________________________________________________________________________
* TestCase04.py  *       LOW      *         19         *       3         *       False     *  None
_________________________________________________________________________________________________________________
* TestCase05.py  *      HIGH      *         31         *       7         *       True     *  test-case failed to execute with following message: b'Traceback (most recent call last):\r\n  File "TestCase05.py", line 28, in <module>\r\n    el.click()\r\nAttributeError: \'NoneType\' object has no attribute \'click\'\r\n'
_________________________________________________________________________________________________________________
* TestCase06.py  *      MEDIUM      *         95         *       29         *       False     *  Server-side error occurred. Please rerun this test-case
_________________________________________________________________________________________________________________
* TestCase07.py  *      HIGH      *         19         *       3         *       True     *  test-case failed to execute with following message: b'Traceback (most recent call last):\r\n  File "TestCase07.py", line 19, in <module>\r\n    el.click()\r\nAttributeError: \'NoneType\' object has no attribute \'click\'\r\n'
_________________________________________________________________________________________________________________
* TestCase08.py  *       LOW      *         25         *       5         *       False     *  None
_________________________________________________________________________________________________________________
* TestCase09.py  *      HIGH      *         17         *       1         *       True     *  test-case failed to execute with following message: b'Traceback (most recent call last):\r\n  File "TestCase09.py", line 8, in <module>\r\n    driver = webdriver.Remote(command_executor=port, desired_capabilities={\'automationName\' : \'UiAutomator2\',\'deviceName\': \'Moto G (5)\',\'platformName\': \'Android\',  \'app\': \'C:/Users/ze0396/Desktop/AGTGA/APKS/Dominos.apk\' , \'autoGrantPermissions\' : \'true\', \'appWaitActivity\' : \'*.*\',\'fullreset\' : \'false\',\'noReset\' : \'true\' } ) \r\n  File "C:\\Users\\ze0396\\AppData\\Local\\Programs\\Python\\Python36\\lib\\site-packages\\appium\\webdriver\\webdriver.py", line 151, in __init__\r\n    proxy\r\n  File "C:\\Users\\ze0396\\AppData\\Local\\Programs\\Python\\Python36\\lib\\site-packages\\selenium\\webdriver\\remote\\webdriver.py", line 157, in __init__\r\n    self.start_session(capabilities, browser_profile)\r\n  File "C:\\Users\\ze0396\\AppData\\Local\\Programs\\Python\\Python36\\lib\\site-packages\\appium\\webdriver\\webdriver.py", line 227, in start_session\r\n    response = self.execute(RemoteCommand.NEW_SESSION, parameters)\r\n  File "C:\\Users\\ze0396\\AppData\\Local\\Programs\\Python\\Python36\\lib\\site-packages\\selenium\\webdriver\\remote\\webdriver.py", line 321, in execute\r\n    self.error_handler.check_response(response)\r\n  File "C:\\Users\\ze0396\\AppData\\Local\\Programs\\Python\\Python36\\lib\\site-packages\\selenium\\webdriver\\remote\\errorhandler.py", line 242, in check_response\r\n    raise exception_class(message, screen, stacktrace)\r\nselenium.common.exceptions.WebDriverException: Message: An unknown server-side error occurred while processing the command. Original error: Cannot start the \'com.dominospizza\' application. Visit https://github.com/appium/appium/blob/master/docs/en/writing-running-appium/android/activity-startup.md for troubleshooting. Original error: Error executing adbExec. Original error: \'Command \'C:\\\\Users\\\\ze0396\\\\AppData\\\\Local\\\\Android\\\\Sdk\\\\platform-tools\\\\adb.exe -P 5037 -s ZY3224HW9F shell am start -W -n com.dominospizza/com.dominos.activities.InitialLaunchActivity -S\' timed out after 20000ms\'. Try to increase the 20000ms adb execution timeout represented by \'adbExecTimeout\' capability\r\n\r\n'
_________________________________________________________________________________________________________________
* TestCase10.py  *      HIGH      *         31         *       5         *       True     *  test-case failed to execute with following message: b'Traceback (most recent call last):\r\n  File "TestCase10.py", line 13, in <module>\r\n    el.click()\r\nAttributeError: \'NoneType\' object has no attribute \'click\'\r\n'
_________________________________________________________________________________________________________________
* TestCase11.py  *       LOW      *         29         *       5         *       False     *  None
_________________________________________________________________________________________________________________
* TestCase12.py  *      HIGH      *         14         *       0         *       True     *  test-case failed to execute with following message: b'Traceback (most recent call last):\r\n  File "TestCase12.py", line 8, in <module>\r\n    driver = webdriver.Remote(command_executor=port, desired_capabilities={\'automationName\' : \'UiAutomator2\',\'deviceName\': \'Moto G (5)\',\'platformName\': \'Android\',  \'app\': \'C:/Users/ze0396/Desktop/AGTGA/APKS/Dominos.apk\' , \'autoGrantPermissions\' : \'true\', \'appWaitActivity\' : \'*.*\',\'fullreset\' : \'false\',\'noReset\' : \'true\' } ) \r\n  File "C:\\Users\\ze0396\\AppData\\Local\\Programs\\Python\\Python36\\lib\\site-packages\\appium\\webdriver\\webdriver.py", line 151, in __init__\r\n    proxy\r\n  File "C:\\Users\\ze0396\\AppData\\Local\\Programs\\Python\\Python36\\lib\\site-packages\\selenium\\webdriver\\remote\\webdriver.py", line 157, in __init__\r\n    self.start_session(capabilities, browser_profile)\r\n  File "C:\\Users\\ze0396\\AppData\\Local\\Programs\\Python\\Python36\\lib\\site-packages\\appium\\webdriver\\webdriver.py", line 227, in start_session\r\n    response = self.execute(RemoteCommand.NEW_SESSION, parameters)\r\n  File "C:\\Users\\ze0396\\AppData\\Local\\Programs\\Python\\Python36\\lib\\site-packages\\selenium\\webdriver\\remote\\webdriver.py", line 321, in execute\r\n    self.error_handler.check_response(response)\r\n  File "C:\\Users\\ze0396\\AppData\\Local\\Programs\\Python\\Python36\\lib\\site-packages\\selenium\\webdriver\\remote\\errorhandler.py", line 242, in check_response\r\n    raise exception_class(message, screen, stacktrace)\r\nselenium.common.exceptions.WebDriverException: Message: An unknown server-side error occurred while processing the command. Original error: Cannot start the \'com.dominospizza\' application. Visit https://github.com/appium/appium/blob/master/docs/en/writing-running-appium/android/activity-startup.md for troubleshooting. Original error: Error executing adbExec. Original error: \'Command \'C:\\\\Users\\\\ze0396\\\\AppData\\\\Local\\\\Android\\\\Sdk\\\\platform-tools\\\\adb.exe -P 5037 -s ZY3224HW9F shell am start -W -n com.dominospizza/com.dominos.activities.InitialLaunchActivity -S\' timed out after 20000ms\'. Try to increase the 20000ms adb execution timeout represented by \'adbExecTimeout\' capability\r\n\r\n'
_________________________________________________________________________________________________________________
*   Average Test-Case Length               =                         97.8
*   Average Action per Test-case           =                         29.0
*****************************************************************************************************************
